Workbook

Sheet Raw_Sales_Data
A1: Transaction_ID | B1: Transaction_Date | C1: Customer_Info | D1: Customer_Id | E1: Customer_Name | F1: Customer_City | G1: Product_Info | H1: Product_ID | I1: Product_Name | J1: Location | K1: Quantity | L1: Unit_Price | M1: Payment_Mode | N1: Salesperson | O1: Category | P1: Brand | Q1: Gst_Rate | R1: Sales_Value | S1: GST_Amount | T1: Total_Value
A2: TXN001 | B2: 46212 | C2: C001-Nandana-Trivandrum | D2: {=_xlfn.TEXTSPLIT(TRIM(C2),"-")} -> C001 | E2: Nandana | F2: Trivandrum | G2: P101-Laptop | H2: {=_xlfn.TEXTSPLIT(TRIM(G2),"-")} -> P101 | I2: Laptop | J2: Trivandrum | K2: 12 | L2: 55000 | M2: Credit Card | N2: Ravi | O2: =VLOOKUP(H2,Product_Master!$A:$E,3,FALSE) -> Electronics | P2: =VLOOKUP(H2,Product_Master!$A:$E,4,FALSE) -> Dell | Q2: =VLOOKUP(H2,Product_Master!$A:$E,5,FALSE) -> 0.18 | R2: =K2*L2 -> 660000 | S2: =R2*Q2 -> 118800 | T2: =R2+S2 -> 778800
A3: TXN002 | B3: 46217 | C3: C002-Joel-Trivandrum | D3: {=_xlfn.TEXTSPLIT(TRIM(C3),"-")} -> C002 | E3: Joel | F3: Trivandrum | G3: P102-Monitor | H3: {=_xlfn.TEXTSPLIT(TRIM(G3),"-")} -> P102 | I3: Monitor | J3: Trivandrum | K3: 10 | L3: 15000 | M3: UPI | N3: Anu | O3: =VLOOKUP(H3,Product_Master!$A:$E,3,FALSE) -> Electronics | P3: =VLOOKUP(H3,Product_Master!$A:$E,4,FALSE) -> LG | Q3: =VLOOKUP(H3,Product_Master!$A:$E,5,FALSE) -> 0.18 | R3: =K3*L3 -> 150000 | S3: =R3*Q3 -> 27000 | T3: =R3+S3 -> 177000 | AA3: QUESTIONS | AB3: ANSWERS
A4: TXN003 | B4: 46210 | C4: C003-Arjun-Kannur | D4: {=_xlfn.TEXTSPLIT(TRIM(C4),"-")} -> C003 | E4: Arjun | F4: Kannur | G4: P101-Laptop | H4: {=_xlfn.TEXTSPLIT(TRIM(G4),"-")} -> P101 | I4: Laptop | J4: Kannur | K4: 9 | L4: 55000 | M4: Debit Card | N4: Ravi | O4: =VLOOKUP(H4,Product_Master!$A:$E,3,FALSE) -> Electronics | P4: =VLOOKUP(H4,Product_Master!$A:$E,4,FALSE) -> Dell | Q4: =VLOOKUP(H4,Product_Master!$A:$E,5,FALSE) -> 0.18 | R4: =K4*L4 -> 495000 | S4: =R4*Q4 -> 89100 | T4: =R4+S4 -> 584100 | V4: TOTAL TRANSACTIONS= | W4: =COUNTA(A2:A251) -> 250
A5: TXN004 | B5: 46226 | C5: C004-Lakshmi-Kollam | D5: {=_xlfn.TEXTSPLIT(TRIM(C5),"-")} -> C004 | E5: Lakshmi | F5: Kollam | G5: P101-Laptop | H5: {=_xlfn.TEXTSPLIT(TRIM(G5),"-")} -> P101 | I5: Laptop | J5: Kollam | K5: 3 | L5: 55000 | M5: Cash | N5: Meera | O5: =VLOOKUP(H5,Product_Master!$A:$E,3,FALSE) -> Electronics | P5: =VLOOKUP(H5,Product_Master!$A:$E,4,FALSE) -> Dell | Q5: =VLOOKUP(H5,Product_Master!$A:$E,5,FALSE) -> 0.18 | R5: =K5*L5 -> 165000 | S5: =R5*Q5 -> 29700 | T5: =R5+S5 -> 194700 | AA5: Which product generated the highest sales value? | AB5: LAPTOP
A6: TXN005 | B6: 46206 | C6: C005-Akhil-Kannur | D6: {=_xlfn.TEXTSPLIT(TRIM(C6),"-")} -> C005 | E6: Akhil | F6: Kannur | G6: P106-Printer | H6: {=_xlfn.TEXTSPLIT(TRIM(G6),"-")} -> P106 | I6: Printer | J6: Kannur | K6: 2 | L6: 12500 | M6: UPI | N6: Meera | O6: =VLOOKUP(H6,Product_Master!$A:$E,3,FALSE) -> Electronics | P6: =VLOOKUP(H6,Product_Master!$A:$E,4,FALSE) -> Canon | Q6: =VLOOKUP(H6,Product_Master!$A:$E,5,FALSE) -> 0.18 | R6: =K6*L6 -> 25000 | S6: =R6*Q6 -> 4500 | T6: =R6+S6 -> 29500 | V6: TOTAL QUANTITY SOLD= | W6: =SUM(K2:K251) -> 1632
A7: TXN006 | B7: 46218 | C7: C006-Sneha-Kollam | D7: {=_xlfn.TEXTSPLIT(TRIM(C7),"-")} -> C006 | E7: Sneha | F7: Kollam | G7: P101-Laptop | H7: {=_xlfn.TEXTSPLIT(TRIM(G7),"-")} -> P101 | I7: Laptop | J7: Kollam | K7: 12 | L7: 55000 | M7: UPI | N7: Suresh | O7: =VLOOKUP(H7,Product_Master!$A:$E,3,FALSE) -> Electronics | P7: =VLOOKUP(H7,Product_Master!$A:$E,4,FALSE) -> Dell | Q7: =VLOOKUP(H7,Product_Master!$A:$E,5,FALSE) -> 0.18 | R7: =K7*L7 -> 660000 | S7: =R7*Q7 -> 118800 | T7: =R7+S7 -> 778800 | AA7: Which salesperson generated the highest sales? | AB7: SURESH
A8: TXN007 | B8: 46210 | C8: C007-Mohammed-Kollam | D8: {=_xlfn.TEXTSPLIT(TRIM(C8),"-")} -> C007 | E8: Mohammed | F8: Kollam | G8: P106-Printer | H8: {=_xlfn.TEXTSPLIT(TRIM(G8),"-")} -> P106 | I8: Printer | J8: Kollam | K8: 10 | L8: 12500 | M8: UPI | N8: Anu | O8: =VLOOKUP(H8,Product_Master!$A:$E,3,FALSE) -> Electronics | P8: =VLOOKUP(H8,Product_Master!$A:$E,4,FALSE) -> Canon | Q8: =VLOOKUP(H8,Product_Master!$A:$E,5,FALSE) -> 0.18 | R8: =K8*L8 -> 125000 | S8: =R8*Q8 -> 22500 | T8: =R8+S8 -> 147500 | V8: TOTAL SALES VALUE= | W8: =SUM(R2:R251) -> 20100550
A9: TXN008 | B9: 46231 | C9: C008-Farhan-Kannur | D9: {=_xlfn.TEXTSPLIT(TRIM(C9),"-")} -> C008 | E9: Farhan | F9: Kannur | G9: P105-Headphones | H9: {=_xlfn.TEXTSPLIT(TRIM(G9),"-")} -> P105 | I9: Headphones | J9: Kannur | K9: 2 | L9: 2500 | M9: UPI | N9: Suresh | O9: =VLOOKUP(H9,Product_Master!$A:$E,3,FALSE) -> Accessories | P9: =VLOOKUP(H9,Product_Master!$A:$E,4,FALSE) -> Sony | Q9: =VLOOKUP(H9,Product_Master!$A:$E,5,FALSE) -> 0.18 | R9: =K9*L9 -> 5000 | S9: =R9*Q9 -> 900 | T9: =R9+S9 -> 5900 | AA9: Which location generated the highest sales? | AB9: THRISSUR
A10: TXN009 | B10: 46215 | C10: C009-Sanjay-Alappuzha | D10: {=_xlfn.TEXTSPLIT(TRIM(C10),"-")} -> C009 | E10: Sanjay | F10: Alappuzha | G10: P106-Printer | H10: {=_xlfn.TEXTSPLIT(TRIM(G10),"-")} -> P106 | I10: Printer | J10: Alappuzha | K10: 3 | L10: 12500 | M10: Credit Card | N10: Meera | O10: =VLOOKUP(H10,Product_Master!$A:$E,3,FALSE) -> Electronics | P10: =VLOOKUP(H10,Product_Master!$A:$E,4,FALSE) -> Canon | Q10: =VLOOKUP(H10,Product_Master!$A:$E,5,FALSE) -> 0.18 | R10: =K10*L10 -> 37500 | S10: =R10*Q10 -> 6750 | T10: =R10+S10 -> 44250 | V10: AVERAGE TRANSATION VALUE= | W10: =AVERAGE(T2:T251) -> 94874.596
A11: TXN010 | B11: 46227 | C11: C010-Swathi-Trivandrum | D11: {=_xlfn.TEXTSPLIT(TRIM(C11),"-")} -> C010 | E11: Swathi | F11: Trivandrum | G11: P103-Keyboard | H11: {=_xlfn.TEXTSPLIT(TRIM(G11),"-")} -> P103 | I11: Keyboard | J11: Trivandrum | K11: 9 | L11: 1200 | M11: Credit Card | N11: Suresh | O11: =VLOOKUP(H11,Product_Master!$A:$E,3,FALSE) -> Accessories | P11: =VLOOKUP(H11,Product_Master!$A:$E,4,FALSE) -> Logitech | Q11: =VLOOKUP(H11,Product_Master!$A:$E,5,FALSE) -> 0.18 | R11: =K11*L11 -> 10800 | S11: =R11*Q11 -> 1944 | T11: =R11+S11 -> 12744 | AA11: Which product category contributed the most sales? | AB11: ELECTRONICS
A12: TXN011 | B12: 46214 | C12: C011-Vishnu-Kollam | D12: {=_xlfn.TEXTSPLIT(TRIM(C12),"-")} -> C011 | E12: Vishnu | F12: Kollam | G12: P104-Mouse | H12: {=_xlfn.TEXTSPLIT(TRIM(G12),"-")} -> P104 | I12: Mouse | J12: Kollam | K12: 11 | L12: 750 | M12: Credit Card | N12: Anu | O12: =VLOOKUP(H12,Product_Master!$A:$E,3,FALSE) -> Accessories | P12: =VLOOKUP(H12,Product_Master!$A:$E,4,FALSE) -> HP | Q12: =VLOOKUP(H12,Product_Master!$A:$E,5,FALSE) -> 0.18 | R12: =K12*L12 -> 8250 | S12: =R12*Q12 -> 1485 | T12: =R12+S12 -> 9735 | V12: MININUM TRANSATION VALUE= | W12: =MIN(T2:T251) -> 885
A13: TXN012 | B13: 46210 | C13: C012-Nikhil-Thrissur | D13: {=_xlfn.TEXTSPLIT(TRIM(C13),"-")} -> C012 | E13: Nikhil | F13: Thrissur | G13: P105-Headphones | H13: {=_xlfn.TEXTSPLIT(TRIM(G13),"-")} -> P105 | I13: Headphones | J13: Thrissur | K13: 2 | L13: 2500 | M13: Cash | N13: Ravi | O13: =VLOOKUP(H13,Product_Master!$A:$E,3,FALSE) -> Accessories | P13: =VLOOKUP(H13,Product_Master!$A:$E,4,FALSE) -> Sony | Q13: =VLOOKUP(H13,Product_Master!$A:$E,5,FALSE) -> 0.18 | R13: =K13*L13 -> 5000 | S13: =R13*Q13 -> 900 | T13: =R13+S13 -> 5900 | AA13: Which payment method was used most frequently? | AB13: CASH
A14: TXN013 | B14: 46218 | C14: C013-Nandana-Alappuzha | D14: {=_xlfn.TEXTSPLIT(TRIM(C14),"-")} -> C013 | E14: Nandana | F14: Alappuzha | G14: P107-Webcam | H14: {=_xlfn.TEXTSPLIT(TRIM(G14),"-")} -> P107 | I14: Webcam | J14: Alappuzha | K14: 11 | L14: 3500 | M14: Cash | N14: Ravi | O14: =VLOOKUP(H14,Product_Master!$A:$E,3,FALSE) -> Electronics | P14: =VLOOKUP(H14,Product_Master!$A:$E,4,FALSE) -> Logitech | Q14: =VLOOKUP(H14,Product_Master!$A:$E,5,FALSE) -> 0.18 | R14: =K14*L14 -> 38500 | S14: =R14*Q14 -> 6930 | T14: =R14+S14 -> 45430 | V14: MAXIMUM TRANSATION VALUE= | W14: =MAX(T2:T251) -> 778800
A15: TXN014 | B15: 46216 | C15: C014-Divya-Kollam | D15: {=_xlfn.TEXTSPLIT(TRIM(C15),"-")} -> C014 | E15: Divya | F15: Kollam | G15: P107-Webcam | H15: {=_xlfn.TEXTSPLIT(TRIM(G15),"-")} -> P107 | I15: Webcam | J15: Kollam | K15: 10 | L15: 3500 | M15: Credit Card | N15: Ravi | O15: =VLOOKUP(H15,Product_Master!$A:$E,3,FALSE) -> Electronics | P15: =VLOOKUP(H15,Product_Master!$A:$E,4,FALSE) -> Logitech | Q15: =VLOOKUP(H15,Product_Master!$A:$E,5,FALSE) -> 0.18 | R15: =K15*L15 -> 35000 | S15: =R15*Q15 -> 6300 | T15: =R15+S15 -> 41300 | AA15: What is the average value of a transaction? | AB15: =AVERAGE(T2:T251) -> 94874.596
A16: TXN015 | B16: 46231 | C16: C015-Meera-Alappuzha | D16: {=_xlfn.TEXTSPLIT(TRIM(C16),"-")} -> C015 | E16: Meera | F16: Alappuzha | G16: P102-Monitor | H16: {=_xlfn.TEXTSPLIT(TRIM(G16),"-")} -> P102 | I16: Monitor | J16: Alappuzha | K16: 1 | L16: 15000 | M16: Credit Card | N16: Ravi | O16: =VLOOKUP(H16,Product_Master!$A:$E,3,FALSE) -> Electronics | P16: =VLOOKUP(H16,Product_Master!$A:$E,4,FALSE) -> LG | Q16: =VLOOKUP(H16,Product_Master!$A:$E,5,FALSE) -> 0.18 | R16: =K16*L16 -> 15000 | S16: =R16*Q16 -> 2700 | T16: =R16+S16 -> 17700
A17: TXN016 | B17: 46216 | C17: C016-Farhan-Thrissur | D17: {=_xlfn.TEXTSPLIT(TRIM(C17),"-")} -> C016 | E17: Farhan | F17: Thrissur | G17: P102-Monitor | H17: {=_xlfn.TEXTSPLIT(TRIM(G17),"-")} -> P102 | I17: Monitor | J17: Thrissur | K17: 7 | L17: 15000 | M17: Debit Card | N17: Asha | O17: =VLOOKUP(H17,Product_Master!$A:$E,3,FALSE) -> Electronics | P17: =VLOOKUP(H17,Product_Master!$A:$E,4,FALSE) -> LG | Q17: =VLOOKUP(H17,Product_Master!$A:$E,5,FALSE) -> 0.18 | R17: =K17*L17 -> 105000 | S17: =R17*Q17 -> 18900 | T17: =R17+S17 -> 123900 | V17: LOCATION | W17: TRANSACTION | X17: TOTAL SALES | AA17: What observations can you make about the sales data? | AB17: Thrissur generating the highest sales despite Kollam recording the highest number of transactions.
A18: TXN017 | B18: 46232 | C18: C017-Sanjay-Kochi | D18: {=_xlfn.TEXTSPLIT(TRIM(C18),"-")} -> C017 | E18: Sanjay | F18: Kochi | G18: P102-Monitor | H18: {=_xlfn.TEXTSPLIT(TRIM(G18),"-")} -> P102 | I18: Monitor | J18: Kochi | K18: 11 | L18: 15000 | M18: Cash | N18: Meera | O18: =VLOOKUP(H18,Product_Master!$A:$E,3,FALSE) -> Electronics | P18: =VLOOKUP(H18,Product_Master!$A:$E,4,FALSE) -> LG | Q18: =VLOOKUP(H18,Product_Master!$A:$E,5,FALSE) -> 0.18 | R18: =K18*L18 -> 165000 | S18: =R18*Q18 -> 29700 | T18: =R18+S18 -> 194700 | V18: THRISSUR | W18: =COUNTIF($J$1:$J$251,V18) -> 31 | X18: =SUMIF($J$2:$J$251,V18,$R$2:$R$251) -> 3974450 | AB18: Malappuram had the lowest number of transactions and Alappuzha has the lowest sales values.
A19: TXN018 | B19: 46218 | C19: C018-Priya-Kollam | D19: {=_xlfn.TEXTSPLIT(TRIM(C19),"-")} -> C018 | E19: Priya | F19: Kollam | G19: P107-Webcam | H19: {=_xlfn.TEXTSPLIT(TRIM(G19),"-")} -> P107 | I19: Webcam | J19: Kollam | K19: 3 | L19: 3500 | M19: Cash | N19: Asha | O19: =VLOOKUP(H19,Product_Master!$A:$E,3,FALSE) -> Electronics | P19: =VLOOKUP(H19,Product_Master!$A:$E,4,FALSE) -> Logitech | Q19: =VLOOKUP(H19,Product_Master!$A:$E,5,FALSE) -> 0.18 | R19: =K19*L19 -> 10500 | S19: =R19*Q19 -> 1890 | T19: =R19+S19 -> 12390 | V19: KOLLAM | W19: =COUNTIF($J$1:$J$251,V19) -> 43 | X19: =SUMIF($J$2:$J$251,V19,$R$2:$R$251) -> 3080650
A20: TXN019 | B20: 46220 | C20: C019-Neha-Trivandrum | D20: {=_xlfn.TEXTSPLIT(TRIM(C20),"-")} -> C019 | E20: Neha | F20: Trivandrum | G20: P105-Headphones | H20: {=_xlfn.TEXTSPLIT(TRIM(G20),"-")} -> P105 | I20: Headphones | J20: Trivandrum | K20: 11 | L20: 2500 | M20: Credit Card | N20: Ravi | O20: =VLOOKUP(H20,Product_Master!$A:$E,3,FALSE) -> Accessories | P20: =VLOOKUP(H20,Product_Master!$A:$E,4,FALSE) -> Sony | Q20: =VLOOKUP(H20,Product_Master!$A:$E,5,FALSE) -> 0.18 | R20: =K20*L20 -> 27500 | S20: =R20*Q20 -> 4950 | T20: =R20+S20 -> 32450 | V20: TRIVANDRUM | W20: =COUNTIF($J$1:$J$251,V20) -> 34 | X20: =SUMIF($J$2:$J$251,V20,$R$2:$R$251) -> 2843750
A21: TXN020 | B21: 46214 | C21: C020-Sneha-Kozhikode | D21: {=_xlfn.TEXTSPLIT(TRIM(C21),"-")} -> C020 | E21: Sneha | F21: Kozhikode | G21: P101-Laptop | H21: {=_xlfn.TEXTSPLIT(TRIM(G21),"-")} -> P101 | I21: Laptop | J21: Kozhikode | K21: 10 | L21: 55000 | M21: UPI | N21: Anu | O21: =VLOOKUP(H21,Product_Master!$A:$E,3,FALSE) -> Electronics | P21: =VLOOKUP(H21,Product_Master!$A:$E,4,FALSE) -> Dell | Q21: =VLOOKUP(H21,Product_Master!$A:$E,5,FALSE) -> 0.18 | R21: =K21*L21 -> 550000 | S21: =R21*Q21 -> 99000 | T21: =R21+S21 -> 649000 | V21: KANNUR | W21: =COUNTIF($J$1:$J$251,V21) -> 36 | X21: =SUMIF($J$2:$J$251,V21,$R$2:$R$251) -> 2697900
A22: TXN021 | B22: 46211 | C22: C021-Sneha-Kollam | D22: {=_xlfn.TEXTSPLIT(TRIM(C22),"-")} -> C021 | E22: Sneha | F22: Kollam | G22: P104-Mouse | H22: {=_xlfn.TEXTSPLIT(TRIM(G22),"-")} -> P104 | I22: Mouse | J22: Kollam | K22: 1 | L22: 750 | M22: UPI | N22: Anu | O22: =VLOOKUP(H22,Product_Master!$A:$E,3,FALSE) -> Accessories | P22: =VLOOKUP(H22,Product_Master!$A:$E,4,FALSE) -> HP | Q22: =VLOOKUP(H22,Product_Master!$A:$E,5,FALSE) -> 0.18 | R22: =K22*L22 -> 750 | S22: =R22*Q22 -> 135 | T22: =R22+S22 -> 885 | V22: KOZHIKODE | W22: =COUNTIF($J$1:$J$251,V22) -> 25 | X22: =SUMIF($J$2:$J$251,V22,$R$2:$R$251) -> 2433900
A23: TXN022 | B23: 46228 | C23: C022-Joel-Alappuzha | D23: {=_xlfn.TEXTSPLIT(TRIM(C23),"-")} -> C022 | E23: Joel | F23: Alappuzha | G23: P102-Monitor | H23: {=_xlfn.TEXTSPLIT(TRIM(G23),"-")} -> P102 | I23: Monitor | J23: Alappuzha | K23: 9 | L23: 15000 | M23: Credit Card | N23: Suresh | O23: =VLOOKUP(H23,Product_Master!$A:$E,3,FALSE) -> Electronics | P23: =VLOOKUP(H23,Product_Master!$A:$E,4,FALSE) -> LG | Q23: =VLOOKUP(H23,Product_Master!$A:$E,5,FALSE) -> 0.18 | R23: =K23*L23 -> 135000 | S23: =R23*Q23 -> 24300 | T23: =R23+S23 -> 159300 | V23: KOCHI | W23: =COUNTIF($J$1:$J$251,V23) -> 29 | X23: =SUMIF($J$2:$J$251,V23,$R$2:$R$251) -> 2040300
A24: TXN023 | B24: 46231 | C24: C023-Ravi-Kozhikode | D24: {=_xlfn.TEXTSPLIT(TRIM(C24),"-")} -> C023 | E24: Ravi | F24: Kozhikode | G24: P105-Headphones | H24: {=_xlfn.TEXTSPLIT(TRIM(G24),"-")} -> P105 | I24: Headphones | J24: Kozhikode | K24: 9 | L24: 2500 | M24: Debit Card | N24: Ravi | O24: =VLOOKUP(H24,Product_Master!$A:$E,3,FALSE) -> Accessories | P24: =VLOOKUP(H24,Product_Master!$A:$E,4,FALSE) -> Sony | Q24: =VLOOKUP(H24,Product_Master!$A:$E,5,FALSE) -> 0.18 | R24: =K24*L24 -> 22500 | S24: =R24*Q24 -> 4050 | T24: =R24+S24 -> 26550 | V24: MALAPPURAM | W24: =COUNTIF($J$1:$J$251,V24) -> 22 | X24: =SUMIF($J$2:$J$251,V24,$R$2:$R$251) -> 1604200
A25: TXN024 | B25: 46225 | C25: C024-Ravi-Kannur | D25: {=_xlfn.TEXTSPLIT(TRIM(C25),"-")} -> C024 | E25: Ravi | F25: Kannur | G25: P105-Headphones | H25: {=_xlfn.TEXTSPLIT(TRIM(G25),"-")} -> P105 | I25: Headphones | J25: Kannur | K25: 7 | L25: 2500 | M25: Cash | N25: Suresh | O25: =VLOOKUP(H25,Product_Master!$A:$E,3,FALSE) -> Accessories | P25: =VLOOKUP(H25,Product_Master!$A:$E,4,FALSE) -> Sony | Q25: =VLOOKUP(H25,Product_Master!$A:$E,5,FALSE) -> 0.18 | R25: =K25*L25 -> 17500 | S25: =R25*Q25 -> 3150 | T25: =R25+S25 -> 20650 | V25: ALAPPUZHA | W25: =COUNTIF($J$1:$J$251,V25) -> 30 | X25: =SUMIF($J$2:$J$251,V25,$R$2:$R$251) -> 1425400
A26: TXN025 | B26: 46211 | C26: C025-Meera-Alappuzha | D26: {=_xlfn.TEXTSPLIT(TRIM(C26),"-")} -> C025 | E26: Meera | F26: Alappuzha | G26: P102-Monitor | H26: {=_xlfn.TEXTSPLIT(TRIM(G26),"-")} -> P102 | I26: Monitor | J26: Alappuzha | K26: 4 | L26: 15000 | M26: Cash | N26: Anu | O26: =VLOOKUP(H26,Product_Master!$A:$E,3,FALSE) -> Electronics | P26: =VLOOKUP(H26,Product_Master!$A:$E,4,FALSE) -> LG | Q26: =VLOOKUP(H26,Product_Master!$A:$E,5,FALSE) -> 0.18 | R26: =K26*L26 -> 60000 | S26: =R26*Q26 -> 10800 | T26: =R26+S26 -> 70800
A27: TXN026 | B27: 46206 | C27: C026-Asha-Kannur | D27: {=_xlfn.TEXTSPLIT(TRIM(C27),"-")} -> C026 | E27: Asha | F27: Kannur | G27: P104-Mouse | H27: {=_xlfn.TEXTSPLIT(TRIM(G27),"-")} -> P104 | I27: Mouse | J27: Kannur | K27: 1 | L27: 750 | M27: UPI | N27: Ravi | O27: =VLOOKUP(H27,Product_Master!$A:$E,3,FALSE) -> Accessories | P27: =VLOOKUP(H27,Product_Master!$A:$E,4,FALSE) -> HP | Q27: =VLOOKUP(H27,Product_Master!$A:$E,5,FALSE) -> 0.18 | R27: =K27*L27 -> 750 | S27: =R27*Q27 -> 135 | T27: =R27+S27 -> 885
A28: TXN027 | B28: 46220 | C28: C027-Mohammed-Kochi | D28: {=_xlfn.TEXTSPLIT(TRIM(C28),"-")} -> C027 | E28: Mohammed | F28: Kochi | G28: P106-Printer | H28: {=_xlfn.TEXTSPLIT(TRIM(G28),"-")} -> P106 | I28: Printer | J28: Kochi | K28: 2 | L28: 12500 | M28: Cash | N28: Suresh | O28: =VLOOKUP(H28,Product_Master!$A:$E,3,FALSE) -> Electronics | P28: =VLOOKUP(H28,Product_Master!$A:$E,4,FALSE) -> Canon | Q28: =VLOOKUP(H28,Product_Master!$A:$E,5,FALSE) -> 0.18 | R28: =K28*L28 -> 25000 | S28: =R28*Q28 -> 4500 | T28: =R28+S28 -> 29500 | V28: HIGHEST SELLING LOCATION= | W28: THRISSUR
A29: TXN028 | B29: 46229 | C29: C028-Arjun-Kozhikode | D29: {=_xlfn.TEXTSPLIT(TRIM(C29),"-")} -> C028 | E29: Arjun | F29: Kozhikode | G29: P108-SSD | H29: {=_xlfn.TEXTSPLIT(TRIM(G29),"-")} -> P108 | I29: SSD | J29: Kozhikode | K29: 4 | L29: 6500 | M29: Debit Card | N29: Ravi | O29: =VLOOKUP(H29,Product_Master!$A:$E,3,FALSE) -> Storage | P29: =VLOOKUP(H29,Product_Master!$A:$E,4,FALSE) -> Samsung | Q29: =VLOOKUP(H29,Product_Master!$A:$E,5,FALSE) -> 0.18 | R29: =K29*L29 -> 26000 | S29: =R29*Q29 -> 4680 | T29: =R29+S29 -> 30680
A30: TXN029 | B30: 46217 | C30: C029-Priya-Trivandrum | D30: {=_xlfn.TEXTSPLIT(TRIM(C30),"-")} -> C029 | E30: Priya | F30: Trivandrum | G30: P107-Webcam | H30: {=_xlfn.TEXTSPLIT(TRIM(G30),"-")} -> P107 | I30: Webcam | J30: Trivandrum | K30: 6 | L30: 3500 | M30: Debit Card | N30: Anu | O30: =VLOOKUP(H30,Product_Master!$A:$E,3,FALSE) -> Electronics | P30: =VLOOKUP(H30,Product_Master!$A:$E,4,FALSE) -> Logitech | Q30: =VLOOKUP(H30,Product_Master!$A:$E,5,FALSE) -> 0.18 | R30: =K30*L30 -> 21000 | S30: =R30*Q30 -> 3780 | T30: =R30+S30 -> 24780
A31: TXN030 | B31: 46227 | C31: C030-Farhan-Trivandrum | D31: {=_xlfn.TEXTSPLIT(TRIM(C31),"-")} -> C030 | E31: Farhan | F31: Trivandrum | G31: P101-Laptop | H31: {=_xlfn.TEXTSPLIT(TRIM(G31),"-")} -> P101 | I31: Laptop | J31: Trivandrum | K31: 7 | L31: 55000 | M31: UPI | N31: Ravi | O31: =VLOOKUP(H31,Product_Master!$A:$E,3,FALSE) -> Electronics | P31: =VLOOKUP(H31,Product_Master!$A:$E,4,FALSE) -> Dell | Q31: =VLOOKUP(H31,Product_Master!$A:$E,5,FALSE) -> 0.18 | R31: =K31*L31 -> 385000 | S31: =R31*Q31 -> 69300 | T31: =R31+S31 -> 454300 | V31: PAYMENT METHORDS | W31: TRANSACTION
A32: TXN031 | B32: 46217 | C32: C031-Arjun-Kannur | D32: {=_xlfn.TEXTSPLIT(TRIM(C32),"-")} -> C031 | E32: Arjun | F32: Kannur | G32: P108-SSD | H32: {=_xlfn.TEXTSPLIT(TRIM(G32),"-")} -> P108 | I32: SSD | J32: Kannur | K32: 3 | L32: 6500 | M32: Cash | N32: Suresh | O32: =VLOOKUP(H32,Product_Master!$A:$E,3,FALSE) -> Storage | P32: =VLOOKUP(H32,Product_Master!$A:$E,4,FALSE) -> Samsung | Q32: =VLOOKUP(H32,Product_Master!$A:$E,5,FALSE) -> 0.18 | R32: =K32*L32 -> 19500 | S32: =R32*Q32 -> 3510 | T32: =R32+S32 -> 23010 | V32: CASH | W32: =COUNTIF($M$2:$M$251,V32) -> 67
A33: TXN032 | B33: 46207 | C33: C032-Divya-Trivandrum | D33: {=_xlfn.TEXTSPLIT(TRIM(C33),"-")} -> C032 | E33: Divya | F33: Trivandrum | G33: P108-SSD | H33: {=_xlfn.TEXTSPLIT(TRIM(G33),"-")} -> P108 | I33: SSD | J33: Trivandrum | K33: 9 | L33: 6500 | M33: UPI | N33: Anu | O33: =VLOOKUP(H33,Product_Master!$A:$E,3,FALSE) -> Storage | P33: =VLOOKUP(H33,Product_Master!$A:$E,4,FALSE) -> Samsung | Q33: =VLOOKUP(H33,Product_Master!$A:$E,5,FALSE) -> 0.18 | R33: =K33*L33 -> 58500 | S33: =R33*Q33 -> 10530 | T33: =R33+S33 -> 69030 | V33: DEBIT CARD | W33: =COUNTIF($M$2:$M$251,V33) -> 66
A34: TXN033 | B34: 46219 | C34: C033-Divya-Kozhikode | D34: {=_xlfn.TEXTSPLIT(TRIM(C34),"-")} -> C033 | E34: Divya | F34: Kozhikode | G34: P107-Webcam | H34: {=_xlfn.TEXTSPLIT(TRIM(G34),"-")} -> P107 | I34: Webcam | J34: Kozhikode | K34: 8 | L34: 3500 | M34: Debit Card | N34: Anu | O34: =VLOOKUP(H34,Product_Master!$A:$E,3,FALSE) -> Electronics | P34: =VLOOKUP(H34,Product_Master!$A:$E,4,FALSE) -> Logitech | Q34: =VLOOKUP(H34,Product_Master!$A:$E,5,FALSE) -> 0.18 | R34: =K34*L34 -> 28000 | S34: =R34*Q34 -> 5040 | T34: =R34+S34 -> 33040 | V34: UPI | W34: =COUNTIF($M$2:$M$251,V34) -> 61
A35: TXN034 | B35: 46212 | C35: C034-Neha-Thrissur | D35: {=_xlfn.TEXTSPLIT(TRIM(C35),"-")} -> C034 | E35: Neha | F35: Thrissur | G35: P101-Laptop | H35: {=_xlfn.TEXTSPLIT(TRIM(G35),"-")} -> P101 | I35: Laptop | J35: Thrissur | K35: 7 | L35: 55000 | M35: Cash | N35: Suresh | O35: =VLOOKUP(H35,Product_Master!$A:$E,3,FALSE) -> Electronics | P35: =VLOOKUP(H35,Product_Master!$A:$E,4,FALSE) -> Dell | Q35: =VLOOKUP(H35,Product_Master!$A:$E,5,FALSE) -> 0.18 | R35: =K35*L35 -> 385000 | S35: =R35*Q35 -> 69300 | T35: =R35+S35 -> 454300 | V35: CREDIT CARD | W35: =COUNTIF($M$2:$M$251,V35) -> 56
A36: TXN035 | B36: 46213 | C36: C035-Swathi-Alappuzha | D36: {=_xlfn.TEXTSPLIT(TRIM(C36),"-")} -> C035 | E36: Swathi | F36: Alappuzha | G36: P103-Keyboard | H36: {=_xlfn.TEXTSPLIT(TRIM(G36),"-")} -> P103 | I36: Keyboard | J36: Alappuzha | K36: 4 | L36: 1200 | M36: UPI | N36: Asha | O36: =VLOOKUP(H36,Product_Master!$A:$E,3,FALSE) -> Accessories | P36: =VLOOKUP(H36,Product_Master!$A:$E,4,FALSE) -> Logitech | Q36: =VLOOKUP(H36,Product_Master!$A:$E,5,FALSE) -> 0.18 | R36: =K36*L36 -> 4800 | S36: =R36*Q36 -> 864 | T36: =R36+S36 -> 5664
A37: TXN036 | B37: 46205 | C37: C036-Joel-Kochi | D37: {=_xlfn.TEXTSPLIT(TRIM(C37),"-")} -> C036 | E37: Joel | F37: Kochi | G37: P106-Printer | H37: {=_xlfn.TEXTSPLIT(TRIM(G37),"-")} -> P106 | I37: Printer | J37: Kochi | K37: 1 | L37: 12500 | M37: Debit Card | N37: Asha | O37: =VLOOKUP(H37,Product_Master!$A:$E,3,FALSE) -> Electronics | P37: =VLOOKUP(H37,Product_Master!$A:$E,4,FALSE) -> Canon | Q37: =VLOOKUP(H37,Product_Master!$A:$E,5,FALSE) -> 0.18 | R37: =K37*L37 -> 12500 | S37: =R37*Q37 -> 2250 | T37: =R37+S37 -> 14750
A38: TXN037 | B38: 46206 | C38: C037-Meera-Kozhikode | D38: {=_xlfn.TEXTSPLIT(TRIM(C38),"-")} -> C037 | E38: Meera | F38: Kozhikode | G38: P101-Laptop | H38: {=_xlfn.TEXTSPLIT(TRIM(G38),"-")} -> P101 | I38: Laptop | J38: Kozhikode | K38: 9 | L38: 55000 | M38: UPI | N38: Asha | O38: =VLOOKUP(H38,Product_Master!$A:$E,3,FALSE) -> Electronics | P38: =VLOOKUP(H38,Product_Master!$A:$E,4,FALSE) -> Dell | Q38: =VLOOKUP(H38,Product_Master!$A:$E,5,FALSE) -> 0.18 | R38: =K38*L38 -> 495000 | S38: =R38*Q38 -> 89100 | T38: =R38+S38 -> 584100 | V38: SALESPERSON | W38: SALES VALIUE
A39: TXN038 | B39: 46234 | C39: C038-Mohammed-Kannur | D39: {=_xlfn.TEXTSPLIT(TRIM(C39),"-")} -> C038 | E39: Mohammed | F39: Kannur | G39: P107-Webcam | H39: {=_xlfn.TEXTSPLIT(TRIM(G39),"-")} -> P107 | I39: Webcam | J39: Kannur | K39: 2 | L39: 3500 | M39: Credit Card | N39: Asha | O39: =VLOOKUP(H39,Product_Master!$A:$E,3,FALSE) -> Electronics | P39: =VLOOKUP(H39,Product_Master!$A:$E,4,FALSE) -> Logitech | Q39: =VLOOKUP(H39,Product_Master!$A:$E,5,FALSE) -> 0.18 | R39: =K39*L39 -> 7000 | S39: =R39*Q39 -> 1260 | T39: =R39+S39 -> 8260 | V39: SURESH | W39: =SUMIF($N$2:$N$251,V39,$R$2:$R$251) -> 5441050
A40: TXN039 | B40: 46225 | C40: C039-Adithya-Kochi | D40: {=_xlfn.TEXTSPLIT(TRIM(C40),"-")} -> C039 | E40: Adithya | F40: Kochi | G40: P102-Monitor | H40: {=_xlfn.TEXTSPLIT(TRIM(G40),"-")} -> P102 | I40: Monitor | J40: Kochi | K40: 7 | L40: 15000 | M40: Cash | N40: Meera | O40: =VLOOKUP(H40,Product_Master!$A:$E,3,FALSE) -> Electronics | P40: =VLOOKUP(H40,Product_Master!$A:$E,4,FALSE) -> LG | Q40: =VLOOKUP(H40,Product_Master!$A:$E,5,FALSE) -> 0.18 | R40: =K40*L40 -> 105000 | S40: =R40*Q40 -> 18900 | T40: =R40+S40 -> 123900 | V40: MEERA | W40: =SUMIF($N$2:$N$251,V40,$R$2:$R$251) -> 4326500
...

Sheet SUMMARY
A1: SUMMARY | B1: RESULT
A3: TOTAL TRANSACTIONS= | B3: 250
A5: TOTAL QUANTITY SOLD= | B5: 1632
A7: TOTAL SALES VALUE= | B7: 20100550
A9: AVERAGE TRANSATION VALUE= | B9: 94874.596
A11: MINIMUM TRANSACTION VALUE= | B11: 885
A13: HIGHEST TRANSATION VALUE= | B13: 778800
A15: TOP SALESPERSON= | B15: SURESH
A17: TOP LOCATION= | B17: THRISSUR
A19: TOP PRODUCT= | B19: LAPTOP
A21: TOP CATEGORY= | B21: ELECTRONICS
A23: MOST USED PAYMENT= | B23: CASH

Sheet Product_Master
A1: Product_ID | B1: Product_Name | C1: Category | D1: Brand | E1: GST_Rate
A2: P101 | B2: Laptop | C2: Electronics | D2: Dell | E2: 0.18
A3: P102 | B3: Monitor | C3: Electronics | D3: LG | E3: 0.18
A4: P103 | B4: Keyboard | C4: Accessories | D4: Logitech | E4: 0.18
A5: P104 | B5: Mouse | C5: Accessories | D5: HP | E5: 0.18
A6: P105 | B6: Headphones | C6: Accessories | D6: Sony | E6: 0.18
A7: P106 | B7: Printer | C7: Electronics | D7: Canon | E7: 0.18
A8: P107 | B8: Webcam | C8: Electronics | D8: Logitech | E8: 0.18
A9: P108 | B9: SSD | C9: Storage | D9: Samsung | E9: 0.18
